Workbook

Sheet Calculation Sheet
B1: TPS26600 Design Calculator Tool
B2: Constants Cells | C2: Input / Select Cells | D2: Calculation Cells
C3: Calculated, but can be over-ridden by the user. Note: Once cells are over-ridden, new calculation sheet should be used for the next design
B4: Parameter | C4: Description | D4: Value | E4: Units | F4: Tolerance
B5: VIN (max) | C5: Maximum System Input Voltage | D5: 14 | E5: V
B6: UVset | C6: Undervoltage Lockout Threshold | D6: 8 | E6: V
B7: OVset | C7: Over Voltage Cut-Off Threshold | D7: 16 | E7: V
B8: Cout | C8: Load Capacitance | D8: 330 | E8: µF | F8: 0.1
B9: TA (max) | C9: Maximum Ambient Temperature | D9: TA = 85C | E9: °C
B10: RLstart | C10: Load during start-up (Assumed to be resistive) | D10: 30 | E10: Ω
B11: Imax | C11: Maximum continuous load current | D11: 1 | E11: A
B12: ILimit | C12: Current Limit, 10% higher than the maximum continuous load current | D12: =MIN(1.1*Imax,2.23) -> 1.1 | E12: A
B14: UVLO, OVP Calculations
B15: R3_sel | C15: Select a value in the range from 10k to 249k | D15: 33 | E15: kΩ | F15: 0.01 | M15: =IF(D15<10, D15*100, IF(AND(D15>=10, D15<100),D15*10,IF(AND(D15>=100, D15<1000), D15, IF(D15>=1000, D15/10)))) -> 330
B16: R2_cal | C16: Calculated value of Resistor at UVLO pin | D16: =D15*((UVLOref*OVset/(UVset*OVPref))-1) -> 33 | E16: kΩ | J16: =D24 -> 7.689939 | K16: Power Fail (VIN Falling) | M16: =IF(D16<10, D16*100, IF(AND(D16>=10, D16<100),D16*10,IF(AND(D16>=100, D16<1000), D16, IF(D16>=1000, D16/10)))) -> 330
B17: R1_cal | C17: Calculated value of Resistor at IN pin | D17: =D15*(OVset/OVPref)*(1-(UVLOref/UVset)) -> 377.69748 | E17: kΩ | J17: =D22 -> 8.3191159 | K17: UVLO (VIN Rising) | M17: =IF(D17<10, D17*100, IF(AND(D17>=10, D17<100),D17*10,IF(AND(D17>=100, D17<1000), D17, IF(D17>=1000, D17/10)))) -> 377.69748
B18: SELECT THE CLOSEST POSSIBLE RESISTANCE VALUE FOR R1, R2, R3 | J18: =D23 -> 16.843642 | K18: OVP (VIN Rising)
B19: R3_sel | C19: Selected closest possible value for R3 resistor | D19: =G19 -> 32.4 | E19: kΩ | F19: =F15 -> 0.01 | G19: =M19*D15/M15 -> 32.4 | M19: =INDEX('Res EIA Tables'!E$5:E$196,MATCH(M15,'Res EIA Tables'!E$5:E$196)) -> 324
B20: R2_sel | C20: Selected closest possible value for R2 resistor | D20: =G20 -> 33.2 | E20: kΩ | F20: =F15 -> 0.01 | G20: =M20*D16/M16 -> 33.2 | M20: =INDEX('Res EIA Tables'!E$5:E$196,2+MATCH(M16,'Res EIA Tables'!E$5:E$196)) -> 332
B21: R1_sel | C21: Selected closest possible value for R1 resistor | D21: 393 | E21: kΩ | F21: =F15 -> 0.01 | G21: =M21*D17/M17 -> 383 | M21: =INDEX('Res EIA Tables'!E$5:E$196,2+MATCH(M17,'Res EIA Tables'!E$5:E$196)) -> 383
B22: UV_Final | C22: =C6 -> Undervoltage Lockout Threshold | D22: =UVLOref*((ROVP+RUVLO+RIN)/(ROVP+RUVLO)) -> 8.3191159 | E22: V | F22: =SQRT(F76^2+F19^2+F20^2+F21^2) -> 0.033778692
B23: OV_Final | C23: =C7 -> Over Voltage Cut-Off Threshold | D23: =OVPref*((ROVP+RUVLO+RIN)/ROVP) -> 16.843642 | E23: V | F23: =SQRT(F78^2+F19^2+F20^2+F21^2) -> 0.033778692
B24: Power Fail Detection | C24: Power Fail Detection Threshold | D24: =(UVLOref-UVLOhys)*((ROVP+RUVLO+RIN)/(ROVP+RUVLO)) -> 7.689939 | E24: V | F24: =F22 -> 0.033778692
B25: I_R123 | C25: Current in R1, R2, R3 Branch | D25: =Vinmax*1000/(ROVP+RUVLO+RIN) -> 30.527693 | E25: uA
B27: Current Limit Calculations
B28: RLIM_cal | C28: Calculated current limit resistor value | D28: =MAX((12/(Ilimit)),5.23) -> 10.909091 | E28: kΩ | F28: 0.01 | J28: =Icharge -> 0.115761 | K28: Inrush Charging Current | M28: =IF(D28<10, D28*100, IF(AND(D28>=10, D28<100),D28*10,IF(AND(D28>=100, D28<1000), D28, IF(D28>=1000, D28/10)))) -> 109.09091
B29: SELECT THE CLOSEST POSSIBLE RESISTANCE VALUE FOR RLIM | J29: =Ilimit_final -> 1.1214953 | K29: Overload Current Limit
B30: RLIM | C30: Selected closest possible value for RLIM resistor | D30: =G30 -> 10.7 | E30: kΩ | F30: =F28 -> 0.01 | G30: =M30*D28/M28 -> 10.7 | J30: =D32 -> 2.0336916 | K30: Fastrip Current Limit | M30: =INDEX('Res EIA Tables'!E$5:E$196,MATCH(M28,'Res EIA Tables'!E$5:E$196)) -> 107
B31: ILimit_Final | C31: Final Current Limit Set Point | D31: =12/Rilim -> 1.1214953 | E31: A | F31: =SQRT(M31^2+F30^2) -> 0.050990195 | M31: =IF(Imax<0.3, 0.12,0.05) -> 0.05
B32: I_Fastrip | C32: Fast-Trip Current Limit to Detect Short Circuit | D32: =Ilimit_final*1.8+0.015 -> 2.0336916 | E32: A | F32: =SQRT(F31^2+0.1^2) -> 0.11224972
B35: dV/dT Capacitor and Start-up Time Calculations
B36: Parameter | C36: Description | D36: Value | E36: Units | F36: Tolerance
B37: Tstart_default | C37: Default start-up time with no external capacitor connected at dVdT pin | D37: =1.6*Vinmax/24 -> 0.93333333 | E37: ms
B38: Tstart_recommended | C38: Recommended start-up time based on 1 / 10th of load current as capacitive charging current | D38: =(Cout*10^-3*OVset)/(Imax*0.1) -> 52.8 | E38: ms
B39: Icharge_recommended | C39: Recommended charging current to charge the load capacitor | D39: =Imax/10 -> 0.1 | E39: A
B40: Tstart_req | C40: Required start-up time | D40: =D38 -> 52.8 | E40: ms
B41: Icharge_req | C41: Charging current required to charge the load capacitor | D41: =D39 -> 0.1 | E41: A
B42: Cdvdt_cal1 | C42: Calculated dVdT capacitor value based on required start-up time | D42: =MAX(((Tstart_req*10^-3*Gain_dvdt*I_dvdt)/OVset),0.01) -> 0.3820113 | E42: µF | F42: =M42 -> 0.1 | M42: =IF(Cdvdt_cal1<=0.1,0.05,0.1) -> 0.1
B43: Cdvdt_cal2 | C43: Calculated dVdT capacitor value based on required charging current | D43: =MAX(((I_dvdt*Gain_dvdt*Cout*10^-6)/Icharge_req),0.01) -> 0.3820113 | E43: µF | F43: 0.05 | M43: =IF(Cdvdt_cal2<=0.1,0.05,0.1) -> 0.1
B44: SELECT THE CLOSEST POSSIBLE CAPACITANCE VALUE FOR CdVdT
...

Sheet Thermal Shutdown Limit Plot
A1: Thermal Shutdown Time (ms) Vs. Power Dissipation (W) | H1: Title of Graph | J1: Thermal Shutdown Time Vs. Power Dissipation
A2: Power Dissipation (W) | B2: TA = -40C | C2: TA = 25C | D2: TA = 85C | E2: TA = 105C | F2: TA = 125C
A3: 1 | B3: 100000 | C3: 100000 | D3: 100000 | E3: 100000 | F3: 100000 | H3: Lable | I3: X-Axis | J3: Power Dissipation (W)
A4: 2 | B4: 100000 | C4: 100000 | D4: 100000 | E4: 100000 | F4: 3640 | I4: Y-Axis | J4: Thermal Shutdown time (ms)
A5: 3 | B5: 100000 | C5: 100000 | D5: 34590 | E5: 2870 | F5: 482
A6: 4 | B6: 100000 | C6: 72350 | D6: 2810 | E6: 681.6 | F6: 174
A7: 5 | B7: 100000 | C7: 13880 | D7: 1497 | E7: 400 | F7: 133.7
A8: 6 | B8: 100000 | C8: 4315 | D8: 638.6 | E8: 250 | F8: 69.76
A9: 7 | B9: 100000 | C9: 2088 | D9: 345 | E9: 142.8 | F9: 39.84
A10: 8 | B10: 59170 | C10: 1147 | D10: 214 | E10: 90.8 | F10: 25.92
A11: 9 | B11: 7000 | C11: 716 | D11: 143.43 | E11: 61.84 | F11: 17.44
A12: 10 | B12: 3275 | C12: 472.76 | D12: 101 | E12: 42.64 | F12: 12.44
A13: 12 | B13: 1172 | C13: 255.7 | D13: 55.33 | E13: 22.8 | F13: 7.4
A14: 14 | B14: 602.6 | C14: 154.3 | D14: 33.78 | E14: 13.92 | F14: 4.98
A15: 16 | B15: 367.2 | C15: 100 | D15: 21.41 | E15: 9.24 | F15: 3.75
A16: 18 | B16: 245.9 | C16: 68.115 | D16: 14.39 | E16: 6.68 | F16: 2.97
... A25: 100 | B25: 2.155 | C25: 1.22 | D25: 0.694 | E25: 0.5067 | F25: 0.3535
C27: Pd (W) | D27: Tstart-up (ms)
B28: Maximum Point | C28: ='Calculation Sheet'!D53 -> 12 | D28: =Tdvdt -> 45.611216
B29: Operating Point | C29: ='Calculation Sheet'!D52 -> 2.3483102 | D29: =D28 -> 45.611216

Sheet Res EIA Tables
A1: Standard EIA Decade Resistor Values
A3: 0.2 | B3: 0.1 | C3: 0.05 | D3: 0.02 | E3: 0.01 | F3: 0.5%, 0.25%, 0.1%
A4: E6 | B4: E12 | C4: E24 | D4: E48 | E4: E96 | F4: E192
A5: 100 | B5: 100 | C5: 100 | D5: 100 | E5: 100 | F5: 100
F6: 101
E7: 102 | F7: 102
F8: 104
D9: 105 | E9: 105 | F9: 105
F10: 106
E11: 107 | F11: 107
F12: 109
C13: 110 | D13: 110 | E13: 110 | F13: 110
F14: 111
E15: 113 | F15: 113
F16: 114
D17: 115 | E17: 115 | F17: 115
F18: 117
E19: 118 | F19: 118
F20: 120
B21: 120 | C21: 120 | D21: 121 | E21: 121 | F21: 121
F22: 123
E23: 124 | F23: 124
F24: 126
D25: 127 | E25: 127 | F25: 127
F26: 129
E27: 130 | F27: 130
F28: 132
C29: 130 | D29: 133 | E29: 133 | F29: 133
F30: 135
E31: 137 | F31: 137
F32: 138
D33: 140 | E33: 140 | F33: 140
F34: 142
E35: 143 | F35: 143
F36: 145
A37: 150 | B37: 150 | C37: 150 | D37: 147 | E37: 147 | F37: 147
F38: 149
E39: 150 | F39: 150
F40: 152
D41: 154 | E41: 154 | F41: 154
...

Sheet Cap Tables
A1: Capacitors Lookup Table
A2: µF
A3: 0.01
A4: 0.015
A5: 0.022
A6: 0.033
A7: 0.047
A8: 0.068
A9: 0.1
A10: 0.15
A11: 0.22
A12: 0.33
A13: 0.47
A14: 0.68
... A27: 100
